Workbook
Name AgentNames: Lists!$H$2:$H$465
Name ResOptions: Lists!$A$2:$A$23
Name ExpOptions: Lists!$B$2:$B$23
Name AuditorNames: Lists!$C$2:$C$16
Name Timeframes: Lists!$D$2:$D$7
Name ValFilter: Lists!$F$2:$F$4
Name TLFilter: Lists!$G$2:$G$41
Name AudFilter: Lists!$I$2:$I$17

Sheet START HERE
B2: 🛡 HP MAINSTREAM EQMS — Excel Edition (live team co-authoring)
B5: HOW THE LIVE SYNC WORKS
B6: This workbook lives in the team's SharePoint 'EQMS' folder. Everyone opens it IN THE BROWSER
B7: (SharePoint > click the file > it opens in Excel Online). Microsoft 365 co-authoring shows every
B8: auditor's entries to everyone else within seconds, automatically. Do NOT download personal copies.
B10: HOW TO LOG AN AUDIT (sheet: Audit Log)
B11: 1. Go to the first empty row, type the Audit Date (shortcut: Ctrl+; inserts today), and
B12: pick the Agent Name from the dropdown — EID, emails, TL, OM, SOM auto-fill instantly.
B13: A RED date cell means the audit has no date yet — it will NOT count on any dashboard
B14: until the date is filled in.
B15: 3. Fill Channel (if blank), Case Number, Genesys Transaction ID.
B16: 4. Pick 'Validation Result / Case Resolution': 'Valid (Pass)' or the invalid defect reason.
... B43: so any mistake can be rolled back. No manual backups needed.

Sheet Dashboard
B1: 🛡 EXECUTIVE DASHBOARD — regular audits (quick cases counted on their own dashboard)
B2: 📅 Timeframe | C2: All Time | D2: 👤 Team Leader | E2: All Team Leaders | F2: 🏷 Auditor | G2: All Auditors | H2: ✅ Validation | I2: All Statuses
B4: REGULAR AUDITS | D4: VALID AUDITS | F4: INVALID AUDITS | H4: INVALID PERCENTAGE
C5: ='Calc'!$B$7 | E5: ='Calc'!$B$8 | G5: ='Calc'!$B$9 | I5: ='Calc'!$B$10
B7: TOP DEFECTIVE RESOLUTION CODE | F7: LATEST AUDIT (FILTERED)
B8: =IF('Calc'!$L$2=0,"—",'Calc'!$K$2&" ("&'Calc'!$L$2&"x)") | F8: ='Calc'!$B$11

Sheet Quick Case Dashboard
B1: ⚡ QUICK CASE DASHBOARD — quick case audits only
B2: 📅 Timeframe | C2: All Time | D2: 👤 Team Leader | E2: All Team Leaders | F2: 🏷 Auditor | G2: All Auditors | H2: ✅ Validation | I2: All Statuses
B4: QUICK CASE AUDITS | D4: VALID AUDITS | F4: INVALID AUDITS | H4: INVALID PERCENTAGE
C5: ='CalcQC'!$B$7 | E5: ='CalcQC'!$B$8 | G5: ='CalcQC'!$B$9 | I5: ='CalcQC'!$B$10
B7: TOP DEFECTIVE RESOLUTION CODE | F7: LATEST AUDIT (FILTERED)
B8: =IF('CalcQC'!$L$2=0,"—",'CalcQC'!$K$2&" ("&'CalcQC'!$L$2&"x)") | F8: ='CalcQC'!$B$11

Sheet Special Codes
B1: 📌 SPECIAL CODES DASHBOARD — Remote Solution · DNAP · SubCan · Void
B2: 📅 Timeframe | C2: All Time | D2: 👤 Team Leader | E2: All Team Leaders | F2: 🏷 Auditor | G2: All Auditors
B4: REMOTE SOLUTION | G4: DNAP
B5: AUDITS | C5: VALID | D5: INVALID | E5: INVALID % | G5: AUDITS | H5: VALID | I5: INVALID | J5: INVALID %
B6: ='CalcCodes'!$F$8 | C6: ='CalcCodes'!$J$8 | D6: ='CalcCodes'!$K$8 | E6: ='CalcCodes'!$L$8 | G6: ='CalcCodes'!$F$9 | H6: ='CalcCodes'!$J$9 | I6: ='CalcCodes'!$K$9 | J6: ='CalcCodes'!$L$9
B10: SUBCAN | G10: VOID
B11: AUDITS | C11: VALID | D11: INVALID | E11: INVALID % | G11: AUDITS | H11: VALID | I11: INVALID | J11: INVALID %
B12: ='CalcCodes'!$F$10 | C12: ='CalcCodes'!$J$10 | D12: ='CalcCodes'!$K$10 | E12: ='CalcCodes'!$L$10 | G12: ='CalcCodes'!$F$11 | H12: ='CalcCodes'!$J$11 | I12: ='CalcCodes'!$K$11 | J12: ='CalcCodes'!$L$11
B16: Counting rule: an audit belongs to a category when its tagged Case Resolution OR its Expected Resolution Code contains the keyword. Categories are independent of the Executive and Quick Case dashboards (those are unchanged) and may overlap each other.

Sheet Audit Log
A1: auditId | B1: auditDate | C1: agentName | D1: agentEid | E1: agentEmail | F1: teamLeader | G1: tlEmail | H1: operationsManager | I1: omEmail | J1: somEmail | K1: channel | L1: lob | M1: caseNumber | N1: genesysTransactionId | O1: validation | P1: caseResolution | Q1: expectedResolutionCode | R1: remarks | S1: auditorName | T1: quickCase | U1: sendEmail
A2: =IF($C2="","","AUD-2026-"&TEXT(ROW()-1,"000000")) | D2: =IF($C2="","",IFERROR(IF(INDEX(Roster!$A:$A,MATCH($C2,Roster!$B:$B,0))="","",INDEX(Roster!$A:$A,MATCH($C2,Roster!$B:$B,0))&""),"—")) | E2: =IF($C2="","",IFERROR(IF(INDEX(Roster!$C:$C,MATCH($C2,Roster!$B:$B,0))="","",INDEX(Roster!$C:$C,MATCH($C2,Roster!$B:$B,0))&""),"—")) | F2: =IF($C2="","",IFERROR(IF(INDEX(Roster!$D:$D,MATCH($C2,Roster!$B:$B,0))="","",INDEX(Roster!$D:$D,MATCH($C2,Roster!$B:$B,0))&""),"—")) | G2: =IF($C2="","",IFERROR(IF(INDEX(Roster!$E:$E,MATCH($C2,Roster!$B:$B,0))="","",INDEX(Roster!$E:$E,MATCH($C2,Roster!$B:$B,0))&""),"—")) | H2: =IF($C2="","",IFERROR(IF(INDEX(Roster!$F:$F,MATCH($C2,Roster!$B:$B,0))="","",INDEX(Roster!$F:$F,MATCH($C2,Roster!$B:$B,0))&""),"—")) | I2: =IF($C2="","",IFERROR(IF(INDEX(Roster!$G:$G,MATCH($C2,Roster!$B:$B,0))="","",INDEX(Roster!$G:$G,MATCH($C2,Roster!$B:$B,0))&""),"—")) | J2: =IF($C2="","",IFERROR(IF(INDEX(Roster!$I:$I,MATCH($C2,Roster!$B:$B,0))="","",INDEX(Roster!$I:$I,MATCH($C2,Roster!$B:$B,0))&""),"—")) | K2: =IF($C2="","",IFERROR(IF(INDEX(Roster!$J:$J,MATCH($C2,Roster!$B:$B,0))="","",INDEX(Roster!$J:$J,MATCH($C2,Roster!$B:$B,0))&""),"—")) | L2: =IF($C2="","",IFERROR(IF(INDEX(Roster!$K:$K,MATCH($C2,Roster!$B:$B,0))="","",INDEX(Roster!$K:$K,MATCH($C2,Roster!$B:$B,0))&""),"—")) | O2: =IF($C2="","",IF($P2="","—",IF($P2="Valid (Pass)","Valid","Invalid"))) | T2: =IF($C2="","",IF(OR(ISNUMBER(SEARCH("quick case",$P2)),ISNUMBER(SEARCH("quick case",$Q2))),"Yes","No")) | U2: =IF($O2="Invalid",HYPERLINK("mailto:"&$G2&";"&$I2&"?cc="&Lists!$E$2&"&subject="&_xlfn.ENCODEURL("[INVALID] Quality audit monitoring completed for "&UPPER($C2))&"&body="&_xlfn.ENCODEURL("Hi "&$F2&","&CHAR(10)&"Good day!"&CHAR(10)&CHAR(10)&"A quality monitoring audit has been completed for "&$C2&"."&CHAR(10)&CHAR(10)&"QUALITY AUDIT DETAILS"&CHAR(10)&"Agent Name: "&$C2&" (EID "&$D2&")"&CHAR(10)&"Audit Date: "&TEXT($B2,"yyyy-mm-dd")&CHAR(10)&"Team Leader: "&$F2&CHAR(10)&"Case Number: "&$M2&CHAR(10)&"Transaction ID: "&$N2&CHAR(10)&"Channel / LOB: "&$K2&" / "&$L2&CHAR(10)&"Evaluator: "&$S2&CHAR(10)&CHAR(10)&"INVALID QUALITY AUDIT DETAILS"&CHAR(10)&"Validation: Invalid"&CHAR(10)&"Invalid Reason: "&$P2&CHAR(10)&"Expected Resolution Code: "&$Q2&CHAR(10)&"Remarks: "&LEFT($R2,600)&CHAR(10)&CHAR(10)&"This is an automated notification from HP Mainstream EQMS."),"✉ Open Email Draft"),"")
A3: =IF($C3="","","AUD-2026-"&TEXT(ROW()-1,"000000")) | D3: =IF($C3="","",IFERROR(IF(INDEX(Roster!$A:$A,MATCH($C3,Roster!$B:$B,0))="","",INDEX(Roster!$A:$A,MATCH($C3,Roster!$B:$B,0))&""),"—")) | E3: =IF($C3="","",IFERROR(IF(INDEX(Roster!$C:$C,MATCH($C3,Roster!$B:$B,0))="","",INDEX(Roster!$C:$C,MATCH($C3,Roster!$B:$B,0))&""),"—")) | F3: =IF($C3="","",IFERROR(IF(INDEX(Roster!$D:$D,MATCH($C3,Roster!$B:$B,0))="","",INDEX(Roster!$D:$D,MATCH($C3,Roster!$B:$B,0))&""),"—")) | G3: =IF($C3="","",IFERROR(IF(INDEX(Roster!$E:$E,MATCH($C3,Roster!$B:$B,0))="","",INDEX(Roster!$E:$E,MATCH($C3,Roster!$B:$B,0))&""),"—")) | H3: =IF($C3="","",IFERROR(IF(INDEX(Roster!$F:$F,MATCH($C3,Roster!$B:$B,0))="","",INDEX(Roster!$F:$F,MATCH($C3,Roster!$B:$B,0))&""),"—")) | I3: =IF($C3="","",IFERROR(IF(INDEX(Roster!$G:$G,MATCH($C3,Roster!$B:$B,0))="","",INDEX(Roster!$G:$G,MATCH($C3,Roster!$B:$B,0))&""),"—")) | J3: =IF($C3="","",IFERROR(IF(INDEX(Roster!$I:$I,MATCH($C3,Roster!$B:$B,0))="","",INDEX(Roster!$I:$I,MATCH($C3,Roster!$B:$B,0))&""),"—")) | K3: =IF($C3="","",IFERROR(IF(INDEX(Roster!$J:$J,MATCH($C3,Roster!$B:$B,0))="","",INDEX(Roster!$J:$J,MATCH($C3,Roster!$B:$B,0))&""),"—")) | L3: =IF($C3="","",IFERROR(IF(INDEX(Roster!$K:$K,MATCH($C3,Roster!$B:$B,0))="","",INDEX(Roster!$K:$K,MATCH($C3,Roster!$B:$B,0))&""),"—")) | O3: =IF($C3="","",IF($P3="","—",IF($P3="Valid (Pass)","Valid","Invalid"))) | T3: =IF($C3="","",IF(OR(ISNUMBER(SEARCH("quick case",$P3)),ISNUMBER(SEARCH("quick case",$Q3))),"Yes","No")) | U3: =IF($O3="Invalid",HYPERLINK("mailto:"&$G3&";"&$I3&"?cc="&Lists!$E$2&"&subject="&_xlfn.ENCODEURL("[INVALID] Quality audit monitoring completed for "&UPPER($C3))&"&body="&_xlfn.ENCODEURL("Hi "&$F3&","&CHAR(10)&"Good day!"&CHAR(10)&CHAR(10)&"A quality monitoring audit has been completed for "&$C3&"."&CHAR(10)&CHAR(10)&"QUALITY AUDIT DETAILS"&CHAR(10)&"Agent Name: "&$C3&" (EID "&$D3&")"&CHAR(10)&"Audit Date: "&TEXT($B3,"yyyy-mm-dd")&CHAR(10)&"Team Leader: "&$F3&CHAR(10)&"Case Number: "&$M3&CHAR(10)&"Transaction ID: "&$N3&CHAR(10)&"Channel / LOB: "&$K3&" / "&$L3&CHAR(10)&"Evaluator: "&$S3&CHAR(10)&CHAR(10)&"INVALID QUALITY AUDIT DETAILS"&CHAR(10)&"Validation: Invalid"&CHAR(10)&"Invalid Reason: "&$P3&CHAR(10)&"Expected Resolution Code: "&$Q3&CHAR(10)&"Remarks: "&LEFT($R3,600)&CHAR(10)&CHAR(10)&"This is an automated notification from HP Mainstream EQMS."),"✉ Open Email Draft"),"")
A4: =IF($C4="","","AUD-2026-"&TEXT(ROW()-1,"000000")) | D4: =IF($C4="","",IFERROR(IF(INDEX(Roster!$A:$A,MATCH($C4,Roster!$B:$B,0))="","",INDEX(Roster!$A:$A,MATCH($C4,Roster!$B:$B,0))&""),"—")) | E4: =IF($C4="","",IFERROR(IF(INDEX(Roster!$C:$C,MATCH($C4,Roster!$B:$B,0))="","",INDEX(Roster!$C:$C,MATCH($C4,Roster!$B:$B,0))&""),"—")) | F4: =IF($C4="","",IFERROR(IF(INDEX(Roster!$D:$D,MATCH($C4,Roster!$B:$B,0))="","",INDEX(Roster!$D:$D,MATCH($C4,Roster!$B:$B,0))&""),"—")) | G4: =IF($C4="","",IFERROR(IF(INDEX(Roster!$E:$E,MATCH($C4,Roster!$B:$B,0))="","",INDEX(Roster!$E:$E,MATCH($C4,Roster!$B:$B,0))&""),"—")) | H4: =IF($C4="","",IFERROR(IF(INDEX(Roster!$F:$F,MATCH($C4,Roster!$B:$B,0))="","",INDEX(Roster!$F:$F,MATCH($C4,Roster!$B:$B,0))&""),"—")) | I4: =IF($C4="","",IFERROR(IF(INDEX(Roster!$G:$G,MATCH($C4,Roster!$B:$B,0))="","",INDEX(Roster!$G:$G,MATCH($C4,Roster!$B:$B,0))&""),"—")) | J4: =IF($C4="","",IFERROR(IF(INDEX(Roster!$I:$I,MATCH($C4,Roster!$B:$B,0))="","",INDEX(Roster!$I:$I,MATCH($C4,Roster!$B:$B,0))&""),"—")) | K4: =IF($C4="","",IFERROR(IF(INDEX(Roster!$J:$J,MATCH($C4,Roster!$B:$B,0))="","",INDEX(Roster!$J:$J,MATCH($C4,Roster!$B:$B,0))&""),"—")) | L4: =IF($C4="","",IFERROR(IF(INDEX(Roster!$K:$K,MATCH($C4,Roster!$B:$B,0))="","",INDEX(Roster!$K:$K,MATCH($C4,Roster!$B:$B,0))&""),"—")) | O4: =IF($C4="","",IF($P4="","—",IF($P4="Valid (Pass)","Valid","Invalid"))) | T4: =IF($C4="","",IF(OR(ISNUMBER(SEARCH("quick case",$P4)),ISNUMBER(SEARCH("quick case",$Q4))),"Yes","No")) | U4: =IF($O4="Invalid",HYPERLINK("mailto:"&$G4&";"&$I4&"?cc="&Lists!$E$2&"&subject="&_xlfn.ENCODEURL("[INVALID] Quality audit monitoring completed for "&UPPER($C4))&"&body="&_xlfn.ENCODEURL("Hi "&$F4&","&CHAR(10)&"Good day!"&CHAR(10)&CHAR(10)&"A quality monitoring audit has been completed for "&$C4&"."&CHAR(10)&CHAR(10)&"QUALITY AUDIT DETAILS"&CHAR(10)&"Agent Name: "&$C4&" (EID "&$D4&")"&CHAR(10)&"Audit Date: "&TEXT($B4,"yyyy-mm-dd")&CHAR(10)&"Team Leader: "&$F4&CHAR(10)&"Case Number: "&$M4&CHAR(10)&"Transaction ID: "&$N4&CHAR(10)&"Channel / LOB: "&$K4&" / "&$L4&CHAR(10)&"Evaluator: "&$S4&CHAR(10)&CHAR(10)&"INVALID QUALITY AUDIT DETAILS"&CHAR(10)&"Validation: Invalid"&CHAR(10)&"Invalid Reason: "&$P4&CHAR(10)&"Expected Resolution Code: "&$Q4&CHAR(10)&"Remarks: "&LEFT($R4,600)&CHAR(10)&CHAR(10)&"This is an automated notification from HP Mainstream EQMS."),"✉ Open Email Draft"),"")
A5: =IF($C5="","","AUD-2026-"&TEXT(ROW()-1,"000000")) | D5: =IF($C5="","",IFERROR(IF(INDEX(Roster!$A:$A,MATCH($C5,Roster!$B:$B,0))="","",INDEX(Roster!$A:$A,MATCH($C5,Roster!$B:$B,0))&""),"—")) | E5: =IF($C5="","",IFERROR(IF(INDEX(Roster!$C:$C,MATCH($C5,Roster!$B:$B,0))="","",INDEX(Roster!$C:$C,MATCH($C5,Roster!$B:$B,0))&""),"—")) | F5: =IF($C5="","",IFERROR(IF(INDEX(Roster!$D:$D,MATCH($C5,Roster!$B:$B,0))="","",INDEX(Roster!$D:$D,MATCH($C5,Roster!$B:$B,0))&""),"—")) | G5: =IF($C5="","",IFERROR(IF(INDEX(Roster!$E:$E,MATCH($C5,Roster!$B:$B,0))="","",INDEX(Roster!$E:$E,MATCH($C5,Roster!$B:$B,0))&""),"—")) | H5: =IF($C5="","",IFERROR(IF(INDEX(Roster!$F:$F,MATCH($C5,Roster!$B:$B,0))="","",INDEX(Roster!$F:$F,MATCH($C5,Roster!$B:$B,0))&""),"—")) | I5: =IF($C5="","",IFERROR(IF(INDEX(Roster!$G:$G,MATCH($C5,Roster!$B:$B,0))="","",INDEX(Roster!$G:$G,MATCH($C5,Roster!$B:$B,0))&""),"—")) | J5: =IF($C5="","",IFERROR(IF(INDEX(Roster!$I:$I,MATCH($C5,Roster!$B:$B,0))="","",INDEX(Roster!$I:$I,MATCH($C5,Roster!$B:$B,0))&""),"—")) | K5: =IF($C5="","",IFERROR(IF(INDEX(Roster!$J:$J,MATCH($C5,Roster!$B:$B,0))="","",INDEX(Roster!$J:$J,MATCH($C5,Roster!$B:$B,0))&""),"—")) | L5: =IF($C5="","",IFERROR(IF(INDEX(Roster!$K:$K,MATCH($C5,Roster!$B:$B,0))="","",INDEX(Roster!$K:$K,MATCH($C5,Roster!$B:$B,0))&""),"—")) | O5: =IF($C5="","",IF($P5="","—",IF($P5="Valid (Pass)","Valid","Invalid"))) | T5: =IF($C5="","",IF(OR(ISNUMBER(SEARCH("quick case",$P5)),ISNUMBER(SEARCH("quick case",$Q5))),"Yes","No")) | U5: =IF($O5="Invalid",HYPERLINK("mailto:"&$G5&";"&$I5&"?cc="&Lists!$E$2&"&subject="&_xlfn.ENCODEURL("[INVALID] Quality audit monitoring completed for "&UPPER($C5))&"&body="&_xlfn.ENCODEURL("Hi "&$F5&","&CHAR(10)&"Good day!"&CHAR(10)&CHAR(10)&"A quality monitoring audit has been completed for "&$C5&"."&CHAR(10)&CHAR(10)&"QUALITY AUDIT DETAILS"&CHAR(10)&"Agent Name: "&$C5&" (EID "&$D5&")"&CHAR(10)&"Audit Date: "&TEXT($B5,"yyyy-mm-dd")&CHAR(10)&"Team Leader: "&$F5&CHAR(10)&"Case Number: "&$M5&CHAR(10)&"Transaction ID: "&$N5&CHAR(10)&"Channel / LOB: "&$K5&" / "&$L5&CHAR(10)&"Evaluator: "&$S5&CHAR(10)&CHAR(10)&"INVALID QUALITY AUDIT DETAILS"&CHAR(10)&"Validation: Invalid"&CHAR(10)&"Invalid Reason: "&$P5&CHAR(10)&"Expected Resolution Code: "&$Q5&CHAR(10)&"Remarks: "&LEFT($R5,600)&CHAR(10)&CHAR(10)&"This is an automated notification from HP Mainstream EQMS."),"✉ Open Email Draft"),"")
A6: =IF($C6="","","AUD-2026-"&TEXT(ROW()-1,"000000")) | D6: =IF($C6="","",IFERROR(IF(INDEX(Roster!$A:$A,MATCH($C6,Roster!$B:$B,0))="","",INDEX(Roster!$A:$A,MATCH($C6,Roster!$B:$B,0))&""),"—")) | E6: =IF($C6="","",IFERROR(IF(INDEX(Roster!$C:$C,MATCH($C6,Roster!$B:$B,0))="","",INDEX(Roster!$C:$C,MATCH($C6,Roster!$B:$B,0))&""),"—")) | F6: =IF($C6="","",IFERROR(IF(INDEX(Roster!$D:$D,MATCH($C6,Roster!$B:$B,0))="","",INDEX(Roster!$D:$D,MATCH($C6,Roster!$B:$B,0))&""),"—")) | G6: =IF($C6="","",IFERROR(IF(INDEX(Roster!$E:$E,MATCH($C6,Roster!$B:$B,0))="","",INDEX(Roster!$E:$E,MATCH($C6,Roster!$B:$B,0))&""),"—")) | H6: =IF($C6="","",IFERROR(IF(INDEX(Roster!$F:$F,MATCH($C6,Roster!$B:$B,0))="","",INDEX(Roster!$F:$F,MATCH($C6,Roster!$B:$B,0))&""),"—")) | I6: =IF($C6="","",IFERROR(IF(INDEX(Roster!$G:$G,MATCH($C6,Roster!$B:$B,0))="","",INDEX(Roster!$G:$G,MATCH($C6,Roster!$B:$B,0))&""),"—")) | J6: =IF($C6="","",IFERROR(IF(INDEX(Roster!$I:$I,MATCH($C6,Roster!$B:$B,0))="","",INDEX(Roster!$I:$I,MATCH($C6,Roster!$B:$B,0))&""),"—")) | K6: =IF($C6="","",IFERROR(IF(INDEX(Roster!$J:$J,MATCH($C6,Roster!$B:$B,0))="","",INDEX(Roster!$J:$J,MATCH($C6,Roster!$B:$B,0))&""),"—")) | L6: =IF($C6="","",IFERROR(IF(INDEX(Roster!$K:$K,MATCH($C6,Roster!$B:$B,0))="","",INDEX(Roster!$K:$K,MATCH($C6,Roster!$B:$B,0))&""),"—")) | O6: =IF($C6="","",IF($P6="","—",IF($P6="Valid (Pass)","Valid","Invalid"))) | T6: =IF($C6="","",IF(OR(ISNUMBER(SEARCH("quick case",$P6)),ISNUMBER(SEARCH("quick case",$Q6))),"Yes","No")) | U6: =IF($O6="Invalid",HYPERLINK("mailto:"&$G6&";"&$I6&"?cc="&Lists!$E$2&"&subject="&_xlfn.ENCODEURL("[INVALID] Quality audit monitoring completed for "&UPPER($C6))&"&body="&_xlfn.ENCODEURL("Hi "&$F6&","&CHAR(10)&"Good day!"&CHAR(10)&CHAR(10)&"A quality monitoring audit has been completed for "&$C6&"."&CHAR(10)&CHAR(10)&"QUALITY AUDIT DETAILS"&CHAR(10)&"Agent Name: "&$C6&" (EID "&$D6&")"&CHAR(10)&"Audit Date: "&TEXT($B6,"yyyy-mm-dd")&CHAR(10)&"Team Leader: "&$F6&CHAR(10)&"Case Number: "&$M6&CHAR(10)&"Transaction ID: "&$N6&CHAR(10)&"Channel / LOB: "&$K6&" / "&$L6&CHAR(10)&"Evaluator: "&$S6&CHAR(10)&CHAR(10)&"INVALID QUALITY AUDIT DETAILS"&CHAR(10)&"Validation: Invalid"&CHAR(10)&"Invalid Reason: "&$P6&CHAR(10)&"Expected Resolution Code: "&$Q6&CHAR(10)&"Remarks: "&LEFT($R6,600)&CHAR(10)&CHAR(10)&"This is an automated notification from HP Mainstream EQMS."),"✉ Open Email Draft"),"")
A7: =IF($C7="","","AUD-2026-"&TEXT(ROW()-1,"000000")) | D7: =IF($C7="","",IFERROR(IF(INDEX(Roster!$A:$A,MATCH($C7,Roster!$B:$B,0))="","",INDEX(Roster!$A:$A,MATCH($C7,Roster!$B:$B,0))&""),"—")) | E7: =IF($C7="","",IFERROR(IF(INDEX(Roster!$C:$C,MATCH($C7,Roster!$B:$B,0))="","",INDEX(Roster!$C:$C,MATCH($C7,Roster!$B:$B,0))&""),"—")) | F7: =IF($C7="","",IFERROR(IF(INDEX(Roster!$D:$D,MATCH($C7,Roster!$B:$B,0))="","",INDEX(Roster!$D:$D,MATCH($C7,Roster!$B:$B,0))&""),"—")) | G7: =IF($C7="","",IFERROR(IF(INDEX(Roster!$E:$E,MATCH($C7,Roster!$B:$B,0))="","",INDEX(Roster!$E:$E,MATCH($C7,Roster!$B:$B,0))&""),"—")) | H7: =IF($C7="","",IFERROR(IF(INDEX(Roster!$F:$F,MATCH($C7,Roster!$B:$B,0))="","",INDEX(Roster!$F:$F,MATCH($C7,Roster!$B:$B,0))&""),"—")) | I7: =IF($C7="","",IFERROR(IF(INDEX(Roster!$G:$G,MATCH($C7,Roster!$B:$B,0))="","",INDEX(Roster!$G:$G,MATCH($C7,Roster!$B:$B,0))&""),"—")) | J7: =IF($C7="","",IFERROR(IF(INDEX(Roster!$I:$I,MATCH($C7,Roster!$B:$B,0))="","",INDEX(Roster!$I:$I,MATCH($C7,Roster!$B:$B,0))&""),"—")) | K7: =IF($C7="","",IFERROR(IF(INDEX(Roster!$J:$J,MATCH($C7,Roster!$B:$B,0))="","",INDEX(Roster!$J:$J,MATCH($C7,Roster!$B:$B,0))&""),"—")) | L7: =IF($C7="","",IFERROR(IF(INDEX(Roster!$K:$K,MATCH($C7,Roster!$B:$B,0))="","",INDEX(Roster!$K:$K,MATCH($C7,Roster!$B:$B,0))&""),"—")) | O7: =IF($C7="","",IF($P7="","—",IF($P7="Valid (Pass)","Valid","Invalid"))) | T7: =IF($C7="","",IF(OR(ISNUMBER(SEARCH("quick case",$P7)),ISNUMBER(SEARCH("quick case",$Q7))),"Yes","No")) | U7: =IF($O7="Invalid",HYPERLINK("mailto:"&$G7&";"&$I7&"?cc="&Lists!$E$2&"&subject="&_xlfn.ENCODEURL("[INVALID] Quality audit monitoring completed for "&UPPER($C7))&"&body="&_xlfn.ENCODEURL("Hi "&$F7&","&CHAR(10)&"Good day!"&CHAR(10)&CHAR(10)&"A quality monitoring audit has been completed for "&$C7&"."&CHAR(10)&CHAR(10)&"QUALITY AUDIT DETAILS"&CHAR(10)&"Agent Name: "&$C7&" (EID "&$D7&")"&CHAR(10)&"Audit Date: "&TEXT($B7,"yyyy-mm-dd")&CHAR(10)&"Team Leader: "&$F7&CHAR(10)&"Case Number: "&$M7&CHAR(10)&"Transaction ID: "&$N7&CHAR(10)&"Channel / LOB: "&$K7&" / "&$L7&CHAR(10)&"Evaluator: "&$S7&CHAR(10)&CHAR(10)&"INVALID QUALITY AUDIT DETAILS"&CHAR(10)&"Validation: Invalid"&CHAR(10)&"Invalid Reason: "&$P7&CHAR(10)&"Expected Resolution Code: "&$Q7&CHAR(10)&"Remarks: "&LEFT($R7,600)&CHAR(10)&CHAR(10)&"This is an automated notification from HP Mainstream EQMS."),"✉ Open Email Draft"),"")
A8: =IF($C8="","","AUD-2026-"&TEXT(ROW()-1,"000000")) | D8: =IF($C8="","",IFERROR(IF(INDEX(Roster!$A:$A,MATCH($C8,Roster!$B:$B,0))="","",INDEX(Roster!$A:$A,MATCH($C8,Roster!$B:$B,0))&""),"—")) | E8: =IF($C8="","",IFERROR(IF(INDEX(Roster!$C:$C,MATCH($C8,Roster!$B:$B,0))="","",INDEX(Roster!$C:$C,MATCH($C8,Roster!$B:$B,0))&""),"—")) | F8: =IF($C8="","",IFERROR(IF(INDEX(Roster!$D:$D,MATCH($C8,Roster!$B:$B,0))="","",INDEX(Roster!$D:$D,MATCH($C8,Roster!$B:$B,0))&""),"—")) | G8: =IF($C8="","",IFERROR(IF(INDEX(Roster!$E:$E,MATCH($C8,Roster!$B:$B,0))="","",INDEX(Roster!$E:$E,MATCH($C8,Roster!$B:$B,0))&""),"—")) | H8: =IF($C8="","",IFERROR(IF(INDEX(Roster!$F:$F,MATCH($C8,Roster!$B:$B,0))="","",INDEX(Roster!$F:$F,MATCH($C8,Roster!$B:$B,0))&""),"—")) | I8: =IF($C8="","",IFERROR(IF(INDEX(Roster!$G:$G,MATCH($C8,Roster!$B:$B,0))="","",INDEX(Roster!$G:$G,MATCH($C8,Roster!$B:$B,0))&""),"—")) | J8: =IF($C8="","",IFERROR(IF(INDEX(Roster!$I:$I,MATCH($C8,Roster!$B:$B,0))="","",INDEX(Roster!$I:$I,MATCH($C8,Roster!$B:$B,0))&""),"—")) | K8: =IF($C8="","",IFERROR(IF(INDEX(Roster!$J:$J,MATCH($C8,Roster!$B:$B,0))="","",INDEX(Roster!$J:$J,MATCH($C8,Roster!$B:$B,0))&""),"—")) | L8: =IF($C8="","",IFERROR(IF(INDEX(Roster!$K:$K,MATCH($C8,Roster!$B:$B,0))="","",INDEX(Roster!$K:$K,MATCH($C8,Roster!$B:$B,0))&""),"—")) | O8: =IF($C8="","",IF($P8="","—",IF($P8="Valid (Pass)","Valid","Invalid"))) | T8: =IF($C8="","",IF(OR(ISNUMBER(SEARCH("quick case",$P8)),ISNUMBER(SEARCH("quick case",$Q8))),"Yes","No")) | U8: =IF($O8="Invalid",HYPERLINK("mailto:"&$G8&";"&$I8&"?cc="&Lists!$E$2&"&subject="&_xlfn.ENCODEURL("[INVALID] Quality audit monitoring completed for "&UPPER($C8))&"&body="&_xlfn.ENCODEURL("Hi "&$F8&","&CHAR(10)&"Good day!"&CHAR(10)&CHAR(10)&"A quality monitoring audit has been completed for "&$C8&"."&CHAR(10)&CHAR(10)&"QUALITY AUDIT DETAILS"&CHAR(10)&"Agent Name: "&$C8&" (EID "&$D8&")"&CHAR(10)&"Audit Date: "&TEXT($B8,"yyyy-mm-dd")&CHAR(10)&"Team Leader: "&$F8&CHAR(10)&"Case Number: "&$M8&CHAR(10)&"Transaction ID: "&$N8&CHAR(10)&"Channel / LOB: "&$K8&" / "&$L8&CHAR(10)&"Evaluator: "&$S8&CHAR(10)&CHAR(10)&"INVALID QUALITY AUDIT DETAILS"&CHAR(10)&"Validation: Invalid"&CHAR(10)&"Invalid Reason: "&$P8&CHAR(10)&"Expected Resolution Code: "&$Q8&CHAR(10)&"Remarks: "&LEFT($R8,600)&CHAR(10)&CHAR(10)&"This is an automated notification from HP Mainstream EQMS."),"✉ Open Email Draft"),"")
A9: =IF($C9="","","AUD-2026-"&TEXT(ROW()-1,"000000")) | D9: =IF($C9="","",IFERROR(IF(INDEX(Roster!$A:$A,MATCH($C9,Roster!$B:$B,0))="","",INDEX(Roster!$A:$A,MATCH($C9,Roster!$B:$B,0))&""),"—")) | E9: =IF($C9="","",IFERROR(IF(INDEX(Roster!$C:$C,MATCH($C9,Roster!$B:$B,0))="","",INDEX(Roster!$C:$C,MATCH($C9,Roster!$B:$B,0))&""),"—")) | F9: =IF($C9="","",IFERROR(IF(INDEX(Roster!$D:$D,MATCH($C9,Roster!$B:$B,0))="","",INDEX(Roster!$D:$D,MATCH($C9,Roster!$B:$B,0))&""),"—")) | G9: =IF($C9="","",IFERROR(IF(INDEX(Roster!$E:$E,MATCH($C9,Roster!$B:$B,0))="","",INDEX(Roster!$E:$E,MATCH($C9,Roster!$B:$B,0))&""),"—")) | H9: =IF($C9="","",IFERROR(IF(INDEX(Roster!$F:$F,MATCH($C9,Roster!$B:$B,0))="","",INDEX(Roster!$F:$F,MATCH($C9,Roster!$B:$B,0))&""),"—")) | I9: =IF($C9="","",IFERROR(IF(INDEX(Roster!$G:$G,MATCH($C9,Roster!$B:$B,0))="","",INDEX(Roster!$G:$G,MATCH($C9,Roster!$B:$B,0))&""),"—")) | J9: =IF($C9="","",IFERROR(IF(INDEX(Roster!$I:$I,MATCH($C9,Roster!$B:$B,0))="","",INDEX(Roster!$I:$I,MATCH($C9,Roster!$B:$B,0))&""),"—")) | K9: =IF($C9="","",IFERROR(IF(INDEX(Roster!$J:$J,MATCH($C9,Roster!$B:$B,0))="","",INDEX(Roster!$J:$J,MATCH($C9,Roster!$B:$B,0))&""),"—")) | L9: =IF($C9="","",IFERROR(IF(INDEX(Roster!$K:$K,MATCH($C9,Roster!$B:$B,0))="","",INDEX(Roster!$K:$K,MATCH($C9,Roster!$B:$B,0))&""),"—")) | O9: =IF($C9="","",IF($P9="","—",IF($P9="Valid (Pass)","Valid","Invalid"))) | T9: =IF($C9="","",IF(OR(ISNUMBER(SEARCH("quick case",$P9)),ISNUMBER(SEARCH("quick case",$Q9))),"Yes","No")) | U9: =IF($O9="Invalid",HYPERLINK("mailto:"&$G9&";"&$I9&"?cc="&Lists!$E$2&"&subject="&_xlfn.ENCODEURL("[INVALID] Quality audit monitoring completed for "&UPPER($C9))&"&body="&_xlfn.ENCODEURL("Hi "&$F9&","&CHAR(10)&"Good day!"&CHAR(10)&CHAR(10)&"A quality monitoring audit has been completed for "&$C9&"."&CHAR(10)&CHAR(10)&"QUALITY AUDIT DETAILS"&CHAR(10)&"Agent Name: "&$C9&" (EID "&$D9&")"&CHAR(10)&"Audit Date: "&TEXT($B9,"yyyy-mm-dd")&CHAR(10)&"Team Leader: "&$F9&CHAR(10)&"Case Number: "&$M9&CHAR(10)&"Transaction ID: "&$N9&CHAR(10)&"Channel / LOB: "&$K9&" / "&$L9&CHAR(10)&"Evaluator: "&$S9&CHAR(10)&CHAR(10)&"INVALID QUALITY AUDIT DETAILS"&CHAR(10)&"Validation: Invalid"&CHAR(10)&"Invalid Reason: "&$P9&CHAR(10)&"Expected Resolution Code: "&$Q9&CHAR(10)&"Remarks: "&LEFT($R9,600)&CHAR(10)&CHAR(10)&"This is an automated notification from HP Mainstream EQMS."),"✉ Open Email Draft"),"")
A10: =IF($C10="","","AUD-2026-"&TEXT(ROW()-1,"000000")) | D10: =IF($C10="","",IFERROR(IF(INDEX(Roster!$A:$A,MATCH($C10,Roster!$B:$B,0))="","",INDEX(Roster!$A:$A,MATCH($C10,Roster!$B:$B,0))&""),"—")) | E10: =IF($C10="","",IFERROR(IF(INDEX(Roster!$C:$C,MATCH($C10,Roster!$B:$B,0))="","",INDEX(Roster!$C:$C,MATCH($C10,Roster!$B:$B,0))&""),"—")) | F10: =IF($C10="","",IFERROR(IF(INDEX(Roster!$D:$D,MATCH($C10,Roster!$B:$B,0))="","",INDEX(Roster!$D:$D,MATCH($C10,Roster!$B:$B,0))&""),"—")) | G10: =IF($C10="","",IFERROR(IF(INDEX(Roster!$E:$E,MATCH($C10,Roster!$B:$B,0))="","",INDEX(Roster!$E:$E,MATCH($C10,Roster!$B:$B,0))&""),"—")) | H10: =IF($C10="","",IFERROR(IF(INDEX(Roster!$F:$F,MATCH($C10,Roster!$B:$B,0))="","",INDEX(Roster!$F:$F,MATCH($C10,Roster!$B:$B,0))&""),"—")) | I10: =IF($C10="","",IFERROR(IF(INDEX(Roster!$G:$G,MATCH($C10,Roster!$B:$B,0))="","",INDEX(Roster!$G:$G,MATCH($C10,Roster!$B:$B,0))&""),"—")) | J10: =IF($C10="","",IFERROR(IF(INDEX(Roster!$I:$I,MATCH($C10,Roster!$B:$B,0))="","",INDEX(Roster!$I:$I,MATCH($C10,Roster!$B:$B,0))&""),"—")) | K10: =IF($C10="","",IFERROR(IF(INDEX(Roster!$J:$J,MATCH($C10,Roster!$B:$B,0))="","",INDEX(Roster!$J:$J,MATCH($C10,Roster!$B:$B,0))&""),"—")) | L10: =IF($C10="","",IFERROR(IF(INDEX(Roster!$K:$K,MATCH($C10,Roster!$B:$B,0))="","",INDEX(Roster!$K:$K,MATCH($C10,Roster!$B:$B,0))&""),"—")) | O10: =IF($C10="","",IF($P10="","—",IF($P10="Valid (Pass)","Valid","Invalid"))) | T10: =IF($C10="","",IF(OR(ISNUMBER(SEARCH("quick case",$P10)),ISNUMBER(SEARCH("quick case",$Q10))),"Yes","No")) | U10: =IF($O10="Invalid",HYPERLINK("mailto:"&$G10&";"&$I10&"?cc="&Lists!$E$2&"&subject="&_xlfn.ENCODEURL("[INVALID] Quality audit monitoring completed for "&UPPER($C10))&"&body="&_xlfn.ENCODEURL("Hi "&$F10&","&CHAR(10)&"Good day!"&CHAR(10)&CHAR(10)&"A quality monitoring audit has been completed for "&$C10&"."&CHAR(10)&CHAR(10)&"QUALITY AUDIT DETAILS"&CHAR(10)&"Agent Name: "&$C10&" (EID "&$D10&")"&CHAR(10)&"Audit Date: "&TEXT($B10,"yyyy-mm-dd")&CHAR(10)&"Team Leader: "&$F10&CHAR(10)&"Case Number: "&$M10&CHAR(10)&"Transaction ID: "&$N10&CHAR(10)&"Channel / LOB: "&$K10&" / "&$L10&CHAR(10)&"Evaluator: "&$S10&CHAR(10)&CHAR(10)&"INVALID QUALITY AUDIT DETAILS"&CHAR(10)&"Validation: Invalid"&CHAR(10)&"Invalid Reason: "&$P10&CHAR(10)&"Expected Resolution Code: "&$Q10&CHAR(10)&"Remarks: "&LEFT($R10,600)&CHAR(10)&CHAR(10)&"This is an automated notification from HP Mainstream EQMS."),"✉ Open Email Draft"),"")
A11: =IF($C11="","","AUD-2026-"&TEXT(ROW()-1,"000000")) | D11: =IF($C11="","",IFERROR(IF(INDEX(Roster!$A:$A,MATCH($C11,Roster!$B:$B,0))="","",INDEX(Roster!$A:$A,MATCH($C11,Roster!$B:$B,0))&""),"—")) | E11: =IF($C11="","",IFERROR(IF(INDEX(Roster!$C:$C,MATCH($C11,Roster!$B:$B,0))="","",INDEX(Roster!$C:$C,MATCH($C11,Roster!$B:$B,0))&""),"—")) | F11: =IF($C11="","",IFERROR(IF(INDEX(Roster!$D:$D,MATCH($C11,Roster!$B:$B,0))="","",INDEX(Roster!$D:$D,MATCH($C11,Roster!$B:$B,0))&""),"—")) | G11: =IF($C11="","",IFERROR(IF(INDEX(Roster!$E:$E,MATCH($C11,Roster!$B:$B,0))="","",INDEX(Roster!$E:$E,MATCH($C11,Roster!$B:$B,0))&""),"—")) | H11: =IF($C11="","",IFERROR(IF(INDEX(Roster!$F:$F,MATCH($C11,Roster!$B:$B,0))="","",INDEX(Roster!$F:$F,MATCH($C11,Roster!$B:$B,0))&""),"—")) | I11: =IF($C11="","",IFERROR(IF(INDEX(Roster!$G:$G,MATCH($C11,Roster!$B:$B,0))="","",INDEX(Roster!$G:$G,MATCH($C11,Roster!$B:$B,0))&""),"—")) | J11: =IF($C11="","",IFERROR(IF(INDEX(Roster!$I:$I,MATCH($C11,Roster!$B:$B,0))="","",INDEX(Roster!$I:$I,MATCH($C11,Roster!$B:$B,0))&""),"—")) | K11: =IF($C11="","",IFERROR(IF(INDEX(Roster!$J:$J,MATCH($C11,Roster!$B:$B,0))="","",INDEX(Roster!$J:$J,MATCH($C11,Roster!$B:$B,0))&""),"—")) | L11: =IF($C11="","",IFERROR(IF(INDEX(Roster!$K:$K,MATCH($C11,Roster!$B:$B,0))="","",INDEX(Roster!$K:$K,MATCH($C11,Roster!$B:$B,0))&""),"—")) | O11: =IF($C11="","",IF($P11="","—",IF($P11="Valid (Pass)","Valid","Invalid"))) | T11: =IF($C11="","",IF(OR(ISNUMBER(SEARCH("quick case",$P11)),ISNUMBER(SEARCH("quick case",$Q11))),"Yes","No")) | U11: =IF($O11="Invalid",HYPERLINK("mailto:"&$G11&";"&$I11&"?cc="&Lists!$E$2&"&subject="&_xlfn.ENCODEURL("[INVALID] Quality audit monitoring completed for "&UPPER($C11))&"&body="&_xlfn.ENCODEURL("Hi "&$F11&","&CHAR(10)&"Good day!"&CHAR(10)&CHAR(10)&"A quality monitoring audit has been completed for "&$C11&"."&CHAR(10)&CHAR(10)&"QUALITY AUDIT DETAILS"&CHAR(10)&"Agent Name: "&$C11&" (EID "&$D11&")"&CHAR(10)&"Audit Date: "&TEXT($B11,"yyyy-mm-dd")&CHAR(10)&"Team Leader: "&$F11&CHAR(10)&"Case Number: "&$M11&CHAR(10)&"Transaction ID: "&$N11&CHAR(10)&"Channel / LOB: "&$K11&" / "&$L11&CHAR(10)&"Evaluator: "&$S11&CHAR(10)&CHAR(10)&"INVALID QUALITY AUDIT DETAILS"&CHAR(10)&"Validation: Invalid"&CHAR(10)&"Invalid Reason: "&$P11&CHAR(10)&"Expected Resolution Code: "&$Q11&CHAR(10)&"Remarks: "&LEFT($R11,600)&CHAR(10)&CHAR(10)&"This is an automated notification from HP Mainstream EQMS."),"✉ Open Email Draft"),"")
A12: =IF($C12="","","AUD-2026-"&TEXT(ROW()-1,"000000")) | D12: =IF($C12="","",IFERROR(IF(INDEX(Roster!$A:$A,MATCH($C12,Roster!$B:$B,0))="","",INDEX(Roster!$A:$A,MATCH($C12,Roster!$B:$B,0))&""),"—")) | E12: =IF($C12="","",IFERROR(IF(INDEX(Roster!$C:$C,MATCH($C12,Roster!$B:$B,0))="","",INDEX(Roster!$C:$C,MATCH($C12,Roster!$B:$B,0))&""),"—")) | F12: =IF($C12="","",IFERROR(IF(INDEX(Roster!$D:$D,MATCH($C12,Roster!$B:$B,0))="","",INDEX(Roster!$D:$D,MATCH($C12,Roster!$B:$B,0))&""),"—")) | G12: =IF($C12="","",IFERROR(IF(INDEX(Roster!$E:$E,MATCH($C12,Roster!$B:$B,0))="","",INDEX(Roster!$E:$E,MATCH($C12,Roster!$B:$B,0))&""),"—")) | H12: =IF($C12="","",IFERROR(IF(INDEX(Roster!$F:$F,MATCH($C12,Roster!$B:$B,0))="","",INDEX(Roster!$F:$F,MATCH($C12,Roster!$B:$B,0))&""),"—")) | I12: =IF($C12="","",IFERROR(IF(INDEX(Roster!$G:$G,MATCH($C12,Roster!$B:$B,0))="","",INDEX(Roster!$G:$G,MATCH($C12,Roster!$B:$B,0))&""),"—")) | J12: =IF($C12="","",IFERROR(IF(INDEX(Roster!$I:$I,MATCH($C12,Roster!$B:$B,0))="","",INDEX(Roster!$I:$I,MATCH($C12,Roster!$B:$B,0))&""),"—")) | K12: =IF($C12="","",IFERROR(IF(INDEX(Roster!$J:$J,MATCH($C12,Roster!$B:$B,0))="","",INDEX(Roster!$J:$J,MATCH($C12,Roster!$B:$B,0))&""),"—")) | L12: =IF($C12="","",IFERROR(IF(INDEX(Roster!$K:$K,MATCH($C12,Roster!$B:$B,0))="","",INDEX(Roster!$K:$K,MATCH($C12,Roster!$B:$B,0))&""),"—")) | O12: =IF($C12="","",IF($P12="","—",IF($P12="Valid (Pass)","Valid","Invalid"))) | T12: =IF($C12="","",IF(OR(ISNUMBER(SEARCH("quick case",$P12)),ISNUMBER(SEARCH("quick case",$Q12))),"Yes","No")) | U12: =IF($O12="Invalid",HYPERLINK("mailto:"&$G12&";"&$I12&"?cc="&Lists!$E$2&"&subject="&_xlfn.ENCODEURL("[INVALID] Quality audit monitoring completed for "&UPPER($C12))&"&body="&_xlfn.ENCODEURL("Hi "&$F12&","&CHAR(10)&"Good day!"&CHAR(10)&CHAR(10)&"A quality monitoring audit has been completed for "&$C12&"."&CHAR(10)&CHAR(10)&"QUALITY AUDIT DETAILS"&CHAR(10)&"Agent Name: "&$C12&" (EID "&$D12&")"&CHAR(10)&"Audit Date: "&TEXT($B12,"yyyy-mm-dd")&CHAR(10)&"Team Leader: "&$F12&CHAR(10)&"Case Number: "&$M12&CHAR(10)&"Transaction ID: "&$N12&CHAR(10)&"Channel / LOB: "&$K12&" / "&$L12&CHAR(10)&"Evaluator: "&$S12&CHAR(10)&CHAR(10)&"INVALID QUALITY AUDIT DETAILS"&CHAR(10)&"Validation: Invalid"&CHAR(10)&"Invalid Reason: "&$P12&CHAR(10)&"Expected Resolution Code: "&$Q12&CHAR(10)&"Remarks: "&LEFT($R12,600)&CHAR(10)&CHAR(10)&"This is an automated notification from HP Mainstream EQMS."),"✉ Open Email Draft"),"")
A13: =IF($C13="","","AUD-2026-"&TEXT(ROW()-1,"000000")) | D13: =IF($C13="","",IFERROR(IF(INDEX(Roster!$A:$A,MATCH($C13,Roster!$B:$B,0))="","",INDEX(Roster!$A:$A,MATCH($C13,Roster!$B:$B,0))&""),"—")) | E13: =IF($C13="","",IFERROR(IF(INDEX(Roster!$C:$C,MATCH($C13,Roster!$B:$B,0))="","",INDEX(Roster!$C:$C,MATCH($C13,Roster!$B:$B,0))&""),"—")) | F13: =IF($C13="","",IFERROR(IF(INDEX(Roster!$D:$D,MATCH($C13,Roster!$B:$B,0))="","",INDEX(Roster!$D:$D,MATCH($C13,Roster!$B:$B,0))&""),"—")) | G13: =IF($C13="","",IFERROR(IF(INDEX(Roster!$E:$E,MATCH($C13,Roster!$B:$B,0))="","",INDEX(Roster!$E:$E,MATCH($C13,Roster!$B:$B,0))&""),"—")) | H13: =IF($C13="","",IFERROR(IF(INDEX(Roster!$F:$F,MATCH($C13,Roster!$B:$B,0))="","",INDEX(Roster!$F:$F,MATCH($C13,Roster!$B:$B,0))&""),"—")) | I13: =IF($C13="","",IFERROR(IF(INDEX(Roster!$G:$G,MATCH($C13,Roster!$B:$B,0))="","",INDEX(Roster!$G:$G,MATCH($C13,Roster!$B:$B,0))&""),"—")) | J13: =IF($C13="","",IFERROR(IF(INDEX(Roster!$I:$I,MATCH($C13,Roster!$B:$B,0))="","",INDEX(Roster!$I:$I,MATCH($C13,Roster!$B:$B,0))&""),"—")) | K13: =IF($C13="","",IFERROR(IF(INDEX(Roster!$J:$J,MATCH($C13,Roster!$B:$B,0))="","",INDEX(Roster!$J:$J,MATCH($C13,Roster!$B:$B,0))&""),"—")) | L13: =IF($C13="","",IFERROR(IF(INDEX(Roster!$K:$K,MATCH($C13,Roster!$B:$B,0))="","",INDEX(Roster!$K:$K,MATCH($C13,Roster!$B:$B,0))&""),"—")) | O13: =IF($C13="","",IF($P13="","—",IF($P13="Valid (Pass)","Valid","Invalid"))) | T13: =IF($C13="","",IF(OR(ISNUMBER(SEARCH("quick case",$P13)),ISNUMBER(SEARCH("quick case",$Q13))),"Yes","No")) | U13: =IF($O13="Invalid",HYPERLINK("mailto:"&$G13&";"&$I13&"?cc="&Lists!$E$2&"&subject="&_xlfn.ENCODEURL("[INVALID] Quality audit monitoring completed for "&UPPER($C13))&"&body="&_xlfn.ENCODEURL("Hi "&$F13&","&CHAR(10)&"Good day!"&CHAR(10)&CHAR(10)&"A quality monitoring audit has been completed for "&$C13&"."&CHAR(10)&CHAR(10)&"QUALITY AUDIT DETAILS"&CHAR(10)&"Agent Name: "&$C13&" (EID "&$D13&")"&CHAR(10)&"Audit Date: "&TEXT($B13,"yyyy-mm-dd")&CHAR(10)&"Team Leader: "&$F13&CHAR(10)&"Case Number: "&$M13&CHAR(10)&"Transaction ID: "&$N13&CHAR(10)&"Channel / LOB: "&$K13&" / "&$L13&CHAR(10)&"Evaluator: "&$S13&CHAR(10)&CHAR(10)&"INVALID QUALITY AUDIT DETAILS"&CHAR(10)&"Validation: Invalid"&CHAR(10)&"Invalid Reason: "&$P13&CHAR(10)&"Expected Resolution Code: "&$Q13&CHAR(10)&"Remarks: "&LEFT($R13,600)&CHAR(10)&CHAR(10)&"This is an automated notification from HP Mainstream EQMS."),"✉ Open Email Draft"),"")
... A2001: =IF($C2001="","","AUD-2026-"&TEXT(ROW()-1,"000000")) | D2001: =IF($C2001="","",IFERROR(IF(INDEX(Roster!$A:$A,MATCH($C2001,Roster!$B:$B,0))="","",INDEX(Roster!$A:$A,MATCH($C2001,Roster!$B:$B,0))&""),"—")) | E2001: =IF($C2001="","",IFERROR(IF(INDEX(Roster!$C:$C,MATCH($C2001,Roster!$B:$B,0))="","",INDEX(Roster!$C:$C,MATCH($C2001,Roster!$B:$B,0))&""),"—")) | F2001: =IF($C2001="","",IFERROR(IF(INDEX(Roster!$D:$D,MATCH($C2001,Roster!$B:$B,0))="","",INDEX(Roster!$D:$D,MATCH($C2001,Roster!$B:$B,0))&""),"—")) | G2001: =IF($C2001="","",IFERROR(IF(INDEX(Roster!$E:$E,MATCH($C2001,Roster!$B:$B,0))="","",INDEX(Roster!$E:$E,MATCH($C2001,Roster!$B:$B,0))&""),"—")) | H2001: =IF($C2001="","",IFERROR(IF(INDEX(Roster!$F:$F,MATCH($C2001,Roster!$B:$B,0))="","",INDEX(Roster!$F:$F,MATCH($C2001,Roster!$B:$B,0))&""),"—")) | I2001: =IF($C2001="","",IFERROR(IF(INDEX(Roster!$G:$G,MATCH($C2001,Roster!$B:$B,0))="","",INDEX(Roster!$G:$G,MATCH($C2001,Roster!$B:$B,0))&""),"—")) | J2001: =IF($C2001="","",IFERROR(IF(INDEX(Roster!$I:$I,MATCH($C2001,Roster!$B:$B,0))="","",INDEX(Roster!$I:$I,MATCH($C2001,Roster!$B:$B,0))&""),"—")) | K2001: =IF($C2001="","",IFERROR(IF(INDEX(Roster!$J:$J,MATCH($C2001,Roster!$B:$B,0))="","",INDEX(Roster!$J:$J,MATCH($C2001,Roster!$B:$B,0))&""),"—")) | L2001: =IF($C2001="","",IFERROR(IF(INDEX(Roster!$K:$K,MATCH($C2001,Roster!$B:$B,0))="","",INDEX(Roster!$K:$K,MATCH($C2001,Roster!$B:$B,0))&""),"—")) | O2001: =IF($C2001="","",IF($P2001="","—",IF($P2001="Valid (Pass)","Valid","Invalid"))) | T2001: =IF($C2001="","",IF(OR(ISNUMBER(SEARCH("quick case",$P2001)),ISNUMBER(SEARCH("quick case",$Q2001))),"Yes","No")) | U2001: =IF($O2001="Invalid",HYPERLINK("mailto:"&$G2001&";"&$I2001&"?cc="&Lists!$E$2&"&subject="&_xlfn.ENCODEURL("[INVALID] Quality audit monitoring completed for "&UPPER($C2001))&"&body="&_xlfn.ENCODEURL("Hi "&$F2001&","&CHAR(10)&"Good day!"&CHAR(10)&CHAR(10)&"A quality monitoring audit has been completed for "&$C2001&"."&CHAR(10)&CHAR(10)&"QUALITY AUDIT DETAILS"&CHAR(10)&"Agent Name: "&$C2001&" (EID "&$D2001&")"&CHAR(10)&"Audit Date: "&TEXT($B2001,"yyyy-mm-dd")&CHAR(10)&"Team Leader: "&$F2001&CHAR(10)&"Case Number: "&$M2001&CHAR(10)&"Transaction ID: "&$N2001&CHAR(10)&"Channel / LOB: "&$K2001&" / "&$L2001&CHAR(10)&"Evaluator: "&$S2001&CHAR(10)&CHAR(10)&"INVALID QUALITY AUDIT DETAILS"&CHAR(10)&"Validation: Invalid"&CHAR(10)&"Invalid Reason: "&$P2001&CHAR(10)&"Expected Resolution Code: "&$Q2001&CHAR(10)&"Remarks: "&LEFT($R2001,600)&CHAR(10)&CHAR(10)&"This is an automated notification from HP Mainstream EQMS."),"✉ Open Email Draft"),"")

Sheet Roster
A1: EmployeeNumber | B1: FullName | C1: Email | D1: ImmediateSupervisor | E1: ImmediateSupervisorEmail | F1: Manager | G1: ManagerEmail | H1: SOM | I1: SOMEmail | J1: CHANNEL | K1: Internal LOB
A2: 101543581 | B2: Abad, Roberto Jr Marquez | C2: roberto.abad1@concentrix.com | D2: Poon, Aris Sobrevilla | E2: aris.poon@concentrix.com | F2: Ramos, Ma Concepcion Sanchez | G2: maconcepcion.ramos@concentrix.com | H2: Ebuenga, Sheryll Avellaneda | I2: sheryll.ebuenga@concentrix.com | K2: HP Mainstream
A3: 103577169 | B3: Abadilla, Paul Justin Aleguiojo | C3: pauljustin.abadilla@concentrix.com | D3: Salafranca, Ryan Alejo | E3: ryan.salafranca@concentrix.com | F3: Arcena, Alberto Chua | G3: alberto.arcenajr@concentrix.com | H3: Ebuenga, Sheryll Avellaneda | I3: sheryll.ebuenga@concentrix.com | K3: HP Mainstream
A4: 103119848 | B4: Abella, Asianicole Cuambot | C4: asianicole.abella@concentrix.com | D4: Blas, Jesus Jr Trinidad | E4: jesus.blas@concentrix.com | F4: Arcena, Alberto Chua | G4: alberto.arcenajr@concentrix.com | H4: Ebuenga, Sheryll Avellaneda | I4: sheryll.ebuenga@concentrix.com | K4: HP Mainstream
A5: 102286678 | B5: Abella, Ma. Divina Centino | C5: madivina.abella@concentrix.com | D5: De Guzman, Gabriel Rodrigo | E5: gabriel.deguzman@concentrix.com | F5: Arcena, Alberto Chua | G5: alberto.arcenajr@concentrix.com | H5: Ebuenga, Sheryll Avellaneda | I5: sheryll.ebuenga@concentrix.com | K5: HP Mainstream
A6: 101778847 | B6: Abellar, Nina Grace Lincallo | C6: ninagrace.abellar@concentrix.com | D6: Adrales, Allen Rick Aguilar | E6: allenrick.adrales@concentrix.com | F6: Ramos, Ma Concepcion Sanchez | G6: maconcepcion.ramos@concentrix.com | H6: Ebuenga, Sheryll Avellaneda | I6: sheryll.ebuenga@concentrix.com | K6: HP Mainstream
A7: 101719087 | B7: Abogado, Maria Cristina Cambaliza | C7: mariacristina.cambaliza@concentrix.com | D7: Dela Fuente, Erick John Palomo | E7: erickjohn.delafuente@concentrix.com | F7: Dela Fuente, Erick John Palomo | G7: erickjohn.delafuente@concentrix.com | H7: Ebuenga, Sheryll Avellaneda | I7: sheryll.ebuenga@concentrix.com | K7: HP Mainstream
A8: 103388575 | B8: Aceron, Ma Jovel Salvador | C8: majovel.aceron@concentrix.com | D8: Hije, Bernadeth Rosales | E8: bernadeth.hije@concentrix.com | F8: Benedicto, Allen Kiel Lazarra | G8: allenkiel.benedicto@concentrix.com | H8: Ebuenga, Sheryll Avellaneda | I8: sheryll.ebuenga@concentrix.com | K8: HP Mainstream
A9: 103577170 | B9: Acuesta, Charles Gerry Stephen Logdat | C9: charlesgerrystephen.acuesta@concentrix.com | D9: Salafranca, Ryan Alejo | E9: ryan.salafranca@concentrix.com | F9: Arcena, Alberto Chua | G9: alberto.arcenajr@concentrix.com | H9: Ebuenga, Sheryll Avellaneda | I9: sheryll.ebuenga@concentrix.com | K9: HP Mainstream
A10: 101483586 | B10: Adrales, Allen Rick Aguilar | C10: allenrick.adrales@concentrix.com | D10: Ramos, Ma Concepcion Sanchez | E10: maconcepcion.ramos@concentrix.com | F10: Ramos, Ma Concepcion Sanchez | G10: maconcepcion.ramos@concentrix.com | H10: Ebuenga, Sheryll Avellaneda | I10: sheryll.ebuenga@concentrix.com | K10: HP Mainstream
A11: 102254768 | B11: Agcaoili, Angel Moraine Hinoo | C11: angelmoraine.agcaoili@concentrix.com | D11: Belandres, Nica Marie Ballola | E11: nicamarie.belandres@concentrix.com | F11: Benedicto, Allen Kiel Lazarra | G11: allenkiel.benedicto@concentrix.com | H11: Ebuenga, Sheryll Avellaneda | I11: sheryll.ebuenga@concentrix.com | K11: HP Mainstream
A12: 101170831 | B12: Aguas, Thea Tolentino | C12: thea.aguas@concentrix.com | D12: Panti, Alger Arellano | E12: alger.panti@concentrix.com | F12: Panti, Alger Arellano | G12: alger.panti@concentrix.com | H12: - | K12: HP Mainstream
A13: 103394144 | B13: Aguto, Luke Matthew Mariano | C13: lukematthew.aguto@concentrix.com | D13: Andrecoso, April Melody Sunga | E13: aprilmelody.andrecoso@concentrix.com | F13: Benedicto, Allen Kiel Lazarra | G13: allenkiel.benedicto@concentrix.com | H13: Ebuenga, Sheryll Avellaneda | I13: sheryll.ebuenga@concentrix.com | K13: HP Mainstream
A14: 101391267 | B14: Ajose, Ferd Mark Cristobal | C14: ferdmark.ajose@concentrix.com | D14: Andrecoso, April Melody Sunga | E14: aprilmelody.andrecoso@concentrix.com | F14: Benedicto, Allen Kiel Lazarra | G14: allenkiel.benedicto@concentrix.com | H14: Ebuenga, Sheryll Avellaneda | I14: sheryll.ebuenga@concentrix.com | K14: HP Mainstream
A15: 101541998 | B15: Albios, Art Christopher Salinas | C15: artchristopher.albios1@concentrix.com | D15: Aluning, Alain-Angelo Cangco | E15: alain-angelo.aluning@concentrix.com | F15: Arcena, Alberto Chua | G15: alberto.arcenajr@concentrix.com | H15: Ebuenga, Sheryll Avellaneda | I15: sheryll.ebuenga@concentrix.com | K15: HP Mainstream
A16: 103415795 | B16: Alcancia, Jaycel Giron | C16: jaycel.alcancia@concentrix.com | D16: Aluning, Alain-Angelo Cangco | E16: alain-angelo.aluning@concentrix.com | F16: Arcena, Alberto Chua | G16: alberto.arcenajr@concentrix.com | H16: Ebuenga, Sheryll Avellaneda | I16: sheryll.ebuenga@concentrix.com | K16: HP Mainstream
A17: 101637247 | B17: Aldea, Arthel Jane Donasco | C17: artheljane.aldea@concentrix.com | D17: Vedia, Jerson Reyes | E17: jerson.vedia@concentrix.com | F17: Ramos, Ma Concepcion Sanchez | G17: maconcepcion.ramos@concentrix.com | H17: Ebuenga, Sheryll Avellaneda | I17: sheryll.ebuenga@concentrix.com | K17: HP Mainstream
A18: 102126373 | B18: Alestre, Jolina Balde | C18: jolina.alestre@concentrix.com | D18: Quinto, Bernadeth Mendoza | E18: bernadeth.quinto@concentrix.com | F18: Benedicto, Allen Kiel Lazarra | G18: allenkiel.benedicto@concentrix.com | H18: Ebuenga, Sheryll Avellaneda | I18: sheryll.ebuenga@concentrix.com | K18: HP Mainstream
A19: 103518200 | B19: Alinday, Shiela Marie Altabano | C19: shielamarie.alinday@concentrix.com | D19: Aluning, Alain-Angelo Cangco | E19: alain-angelo.aluning@concentrix.com | F19: Arcena, Alberto Chua | G19: alberto.arcenajr@concentrix.com | H19: Ebuenga, Sheryll Avellaneda | I19: sheryll.ebuenga@concentrix.com | K19: HP Mainstream
A20: 101023718 | B20: Almiñe, Jaypee Maniquiz | C20: jaypee.almine@concentrix.com | D20: Racha, Grace Eunice Divinagracia | E20: graceeunice.racha@concentrix.com | F20: Ramos, Ma Concepcion Sanchez | G20: maconcepcion.ramos@concentrix.com | H20: Ebuenga, Sheryll Avellaneda | I20: sheryll.ebuenga@concentrix.com | K20: HP Mainstream
A21: 476138 | B21: Almodiel, Shaileen Eduarte | C21: shaileen.almodiel@concentrix.com | D21: Chan, Caroline Cruce | E21: caroline.chan@concentrix.com | F21: Chan, Caroline Cruce | G21: caroline.chan@concentrix.com | H21: - | K21: HP Mainstream
A22: 454921 | B22: Aluning, Alain-Angelo Cangco | C22: alain-angelo.aluning@concentrix.com | D22: Arcena, Alberto Chua | E22: alberto.arcenajr@concentrix.com | F22: Arcena, Alberto Chua | G22: alberto.arcenajr@concentrix.com | H22: Ebuenga, Sheryll Avellaneda | I22: sheryll.ebuenga@concentrix.com | K22: HP Mainstream
A23: 102867414 | B23: Alvarez, Wenerick Francisco | C23: wenerick.alvarez@concentrix.com | D23: Ferrer, Jasper Kenneth Labor | E23: jasperkenneth.ferrer@concentrix.com | F23: Nito, Reynaldo Tribol | G23: reynaldo.nito@concentrix.com | H23: Ebuenga, Sheryll Avellaneda | I23: sheryll.ebuenga@concentrix.com | K23: HP Mainstream
A24: 103188741 | B24: Amboyon, Julieta Mata | C24: julieta.amboyon@concentrix.com | D24: Vedia, Jerson Reyes | E24: jerson.vedia@concentrix.com | F24: Ramos, Ma Concepcion Sanchez | G24: maconcepcion.ramos@concentrix.com | H24: Ebuenga, Sheryll Avellaneda | I24: sheryll.ebuenga@concentrix.com | K24: HP Mainstream
A25: 102113167 | B25: Andrecoso, April Melody Sunga | C25: aprilmelody.andrecoso@concentrix.com | D25: Benedicto, Allen Kiel Lazarra | E25: allenkiel.benedicto@concentrix.com | F25: Benedicto, Allen Kiel Lazarra | G25: allenkiel.benedicto@concentrix.com | H25: Ebuenga, Sheryll Avellaneda | I25: sheryll.ebuenga@concentrix.com | K25: HP Mainstream
A26: 102044380 | B26: Anilado, Ellen Sunga | C26: ellen.anilado@concentrix.com | D26: Racha, Grace Eunice Divinagracia | E26: graceeunice.racha@concentrix.com | F26: Ramos, Ma Concepcion Sanchez | G26: maconcepcion.ramos@concentrix.com | H26: Ebuenga, Sheryll Avellaneda | I26: sheryll.ebuenga@concentrix.com | K26: HP Mainstream
A27: 103577938 | B27: Antonio, Jeric Camillan | C27: jeric.antonio1@concentrix.com | D27: Sheilick Anne Munoz | F27: Pineda, Gerald Christian Bo | G27: geraldchristian.pineda@concentrix.com | H27: Medel, Lorelei Gabriel | I27: lorelei.gabriel@concentrix.com | K27: HP Mainstream
A28: 103378689 | B28: Antonio, Marvin Molo | C28: marvin.antonio@concentrix.com | D28: Ugalino, Jonadel Pineda | E28: jonadel.ugalino@concentrix.com | F28: Benedicto, Allen Kiel Lazarra | G28: allenkiel.benedicto@concentrix.com | H28: Ebuenga, Sheryll Avellaneda | I28: sheryll.ebuenga@concentrix.com | K28: HP Mainstream
A29: 102160525 | B29: Antonio, Patricia Ann Valdez | C29: patriciaann.antonio@concentrix.com | D29: Ferrer, Jasper Kenneth Labor | E29: jasperkenneth.ferrer@concentrix.com | F29: Nito, Reynaldo Tribol | G29: reynaldo.nito@concentrix.com | H29: Ebuenga, Sheryll Avellaneda | I29: sheryll.ebuenga@concentrix.com | K29: HP Mainstream
A30: 103518201 | B30: Apostol, Shaira Nmn | C30: shaira.apostol@concentrix.com | D30: Racha, Grace Eunice Divinagracia | E30: graceeunice.racha@concentrix.com | F30: Ramos, Ma Concepcion Sanchez | G30: maconcepcion.ramos@concentrix.com | H30: Ebuenga, Sheryll Avellaneda | I30: sheryll.ebuenga@concentrix.com | K30: HP Mainstream
A31: 102047216 | B31: Apuang, Cecilia Basilga | C31: cecilia.apuang@concentrix.com | D31: Poon, Aris Sobrevilla | E31: aris.poon@concentrix.com | F31: Ramos, Ma Concepcion Sanchez | G31: maconcepcion.ramos@concentrix.com | H31: Ebuenga, Sheryll Avellaneda | I31: sheryll.ebuenga@concentrix.com | K31: HP Mainstream
A32: 101571853 | B32: Aquino, Ricky Nido | C32: ricky.aquino@concentrix.com | D32: Luñiza, Jona Claveria | E32: jona.luniza@concentrix.com | F32: Arcena, Alberto Chua | G32: alberto.arcenajr@concentrix.com | H32: Ebuenga, Sheryll Avellaneda | I32: sheryll.ebuenga@concentrix.com | K32: HP Mainstream
A33: 103189120 | B33: Aramburo Jr., Romeo Marzan | C33: romeo.aramburojr@concentrix.com | D33: Vedia, Jerson Reyes | E33: jerson.vedia@concentrix.com | F33: Ramos, Ma Concepcion Sanchez | G33: maconcepcion.ramos@concentrix.com | H33: Ebuenga, Sheryll Avellaneda | I33: sheryll.ebuenga@concentrix.com | K33: HP Mainstream
A34: 145670 | B34: Arcena, Alberto Chua | C34: alberto.arcenajr@concentrix.com | D34: Sevilla, Audrey Marie Galindo | E34: audrey.galindosevilla@concentrix.com | F34: - | H34: - | K34: HP Mainstream
A35: 101245258 | B35: Aringo, Ivy Mical Jugo | C35: ivymical.aringo@concentrix.com | D35: Cinco, Neville Dimagiba | E35: neville.cinco@concentrix.com | F35: Christian Bajo | H35: - | K35: HP Mainstream
A36: 103075166 | B36: Arnado, Ricardo Agapito Guison | C36: ricardoagapito.arnado@concentrix.com | D36: Blas, Jesus Jr Trinidad | E36: jesus.blas@concentrix.com | F36: Arcena, Alberto Chua | G36: alberto.arcenajr@concentrix.com | H36: Ebuenga, Sheryll Avellaneda | I36: sheryll.ebuenga@concentrix.com | K36: HP Mainstream
A37: 101495993 | B37: Arriola, Kathrine Kae Advincula | C37: kathrinekae.arriola@concentrix.com | D37: Cinco, Neville Dimagiba | E37: neville.cinco@concentrix.com | F37: Christian Bajo | H37: - | K37: HP Mainstream
A38: 102078871 | B38: Arsenue, Melvin Rosario | C38: melvin.arsenue@concentrix.com | D38: Ugalino, Jonadel Pineda | E38: jonadel.ugalino@concentrix.com | F38: Benedicto, Allen Kiel Lazarra | G38: allenkiel.benedicto@concentrix.com | H38: Ebuenga, Sheryll Avellaneda | I38: sheryll.ebuenga@concentrix.com | K38: HP Mainstream
A39: 101556076 | B39: Asenas, Sheryll Mae Futalan | C39: sheryllmae.asenas@concentrix.com | D39: Galope, Danri Catacutan | E39: danri.galope@concentrix.com | F39: Ramos, Ma Concepcion Sanchez | G39: maconcepcion.ramos@concentrix.com | H39: Ebuenga, Sheryll Avellaneda | I39: sheryll.ebuenga@concentrix.com | K39: HP Mainstream
A40: 102206550 | B40: Awitan, Jane Arimado | C40: jane.awitan@concentrix.com | D40: Andrecoso, April Melody Sunga | E40: aprilmelody.andrecoso@concentrix.com | F40: Benedicto, Allen Kiel Lazarra | G40: allenkiel.benedicto@concentrix.com | H40: Ebuenga, Sheryll Avellaneda | I40: sheryll.ebuenga@concentrix.com | K40: HP Mainstream
...

Sheet Lists
A1: Case Resolution options | B1: Expected Resolution Codes | C1: Auditors | D1: Timeframes | E1: CC distribution list (edit) | F1: Validation filter | G1: Team Leaders | H1: Agent Names | I1: Auditor filter | K1: Channels
A2: Valid (Pass) | B2: Remote Solution (HW/SW Resolved Remotely via Troubleshooting) | C2: Sundeep Bhardwaj | D2: All Time | E2: PH_QUE_NE_HP_Quality_Support@concentrix.com | F2: All Statuses | G2: All Team Leaders | H2: Abad, Roberto Jr Marquez | I2: All Auditors | K2: Voice
A3: Quick Case (Invalid) | B3: Parts Shipped (CSR Part / RCD Media / Instant Ink PO) | C3: Ivy Serata | D3: Today | F3: Valid | G3: Adrales, Allen Rick Aguilar | H3: Abadilla, Paul Justin Aleguiojo | I3: Sundeep Bhardwaj | K3: Chat
A4: No Support Provided (Security Stop/Hold / Global Trade Fail) | B4: Onsite Solution (Break & Fix / Installation Work Order) | C4: Jonel Meniano | D4: Last 7 Days | F4: Invalid | G4: Agustin, Alexander Veloso | H4: Abella, Asianicole Cuambot | I4: Ivy Serata | K4: Email
A5: Cancel Per Customer / No Contact (CPC/NC) | B5: Offsite Solution (Bench / Depot Repair Service Order) | C5: Archieval Decena | D5: Last 14 Days | G5: Aluning, Alain-Angelo Cangco | H5: Abella, Ma. Divina Centino | I5: Jonel Meniano | K5: Back Office
A6: Case Voided (Test Case / Duplicate / Created by Mistake) | B6: Exchange Solution (Whole Unit Exchange Arranged) | C6: Donnah Brual | D6: Last 30 Days | G6: Andrecoso, April Melody Sunga | H6: Abellar, Nina Grace Lincallo | I6: Archieval Decena
A7: Non-Tech Solution (General Inquiry / Warranty / How-To) | B7: Non-Tech Solution (General Inquiry / Warranty / How-To) | C7: Emil Eduardo | D7: This Month | G7: Arcena, Alberto Chua | H7: Abogado, Maria Cristina Cambaliza | I7: Donnah Brual
A8: Remote Solution (HW/SW Resolved Remotely via Troubleshooting) | B8: Cloud Recovery Download (Recovery Media with No Tech Concern) | C8: Maevenus Setias | G8: Bajo, Christian Dela Cruz | H8: Aceron, Ma Jovel Salvador | I8: Emil Eduardo
A9: Offsite Solution (Bench / Depot Repair Service Order) | B9: Referred - for Hardware Service (ASP / 3rd Party HW / DOA) | C9: Kurtjohn Gatmaitan | G9: Belandres, Nica Marie Ballola | H9: Acuesta, Charles Gerry Stephen Logdat | I9: Maevenus Setias
A10: Exchange Solution (Whole Unit Exchange Arranged) | B10: Referred - for Software Support (Out of Scope / 3rd Party SW) | C10: Attinareccie Padaya | G10: Benedicto, Allen Kiel Lazarra | H10: Adrales, Allen Rick Aguilar | I10: Kurtjohn Gatmaitan
A11: Onsite Solution (Break & Fix / Installation Work Order) | B11: Quick Case | C11: Christian Pila | G11: Blas, Jesus Jr Trinidad | H11: Agcaoili, Angel Moraine Hinoo | I11: Attinareccie Padaya
A12: Parts Shipped (CSR Part / RCD Media / Instant Ink PO) | B12: No Support Provided (Security Stop/Hold / Global Trade Fail) | C12: Shaileen Almodiel | G12: Briones, Aries Ang | H12: Aguas, Thea Tolentino | I12: Christian Pila
A13: Referred - for Hardware Service (ASP / 3rd Party HW / DOA) | B13: Cancel Per Customer / No Contact (CPC/NC) | C13: Darlene Presado | G13: Chan, Caroline Cruce | H13: Aguto, Luke Matthew Mariano | I13: Shaileen Almodiel
A14: Referred - for Software Support (Out of Scope / 3rd Party SW) | B14: Case Voided (Test Case / Duplicate / Created by Mistake) | C14: Anita Fabales | G14: Cinco, Neville Dimagiba | H14: Ajose, Ferd Mark Cristobal | I14: Darlene Presado
A15: Unresolved - Not Entitled for Support | B15: Unresolved - Not Entitled for Support | C15: Jessalyn Sastrillo | G15: De Guzman, Gabriel Rodrigo | H15: Albios, Art Christopher Salinas | I15: Anita Fabales
C16: Caroline Chan | G16: Dela Fuente, Erick John Palomo | H16: Alcancia, Jaycel Giron | I16: Jessalyn Sastrillo
G17: Ebuenga, Sheryll Avellaneda | H17: Aldea, Arthel Jane Donasco | I17: Caroline Chan
G18: Ferrer, Jasper Kenneth Labor | H18: Alestre, Jolina Balde
G19: Galope, Danri Catacutan | H19: Alinday, Shiela Marie Altabano
G20: Hije, Bernadeth Rosales | H20: Almiñe, Jaypee Maniquiz
G21: Imran Shaikh | H21: Almodiel, Shaileen Eduarte
G22: Lazaro, Paolo Dennis Hidalgo | H22: Aluning, Alain-Angelo Cangco
G23: Leonardo, Kristine Joy Sigalat | H23: Alvarez, Wenerick Francisco
G24: Lungcay, Robin Landayan | H24: Amboyon, Julieta Mata
G25: Luñiza, Jona Claveria | H25: Andrecoso, April Melody Sunga
G26: Medel, Lorelei Gabriel | H26: Anilado, Ellen Sunga
G27: Napone, Jerome Budlao | H27: Antonio, Jeric Camillan
G28: Nito, Reynaldo Tribol | H28: Antonio, Marvin Molo
G29: Ong, Lesley Ann Bayotas | H29: Antonio, Patricia Ann Valdez
... G41: Vedia, Jerson Reyes | H41: Baguino, Ariel Forbes
H42: Balingit, Judy Ann Getubig
H43: Balles, Reymund Esquivel
H44: Baloco, Paula Bianca Villarante
H45: Baltazar, Ryan Casey Lansangan
H46: Basbas, Lea Mai Lado
H47: Batimana, Randy Pardilla
H48: Bautista, Allan Joseph Sanchez
H49: Bautista, Arvie Aggabao
H50: Baya, Cindy Diaz
H51: Bayson, Johnnella Faith Baluco
...

Sheet Calc
A1: filter engine | D1: day | E1: audits | G1: invalid reason | H1: defects | I1: rank helper | K1: top code | L1: defects | N1: TL | O1: audits | P1: valid | Q1: rank | R1: pass | T1: top TL | U1: audits | V1: pass % | X1: agent | Y1: defects | Z1: rank | AB1: top agent | AC1: defects
A2: startDate | B2: =IF('Dashboard'!$C$2="All Time",0,IF('Dashboard'!$C$2="Today",TODAY(),IF('Dashboard'!$C$2="Last 7 Days",TODAY()-6,IF('Dashboard'!$C$2="Last 14 Days",TODAY()-13,IF('Dashboard'!$C$2="Last 30 Days",TODAY()-29,DATE(YEAR(TODAY()),MONTH(TODAY()),1)))))) | D2: =TODAY()-13 | E2: =COUNTIFS('Audit Log'!$B$2:$B$2001,$D2,'Audit Log'!$F$2:$F$2001,$B$3,'Audit Log'!$S$2:$S$2001,$B$4,'Audit Log'!$T$2:$T$2001,"No",'Audit Log'!$O$2:$O$2001,$B$5) | G2: Quick Case (Invalid) | H2: =COUNTIFS('Audit Log'!$B$2:$B$2001,">="&$B$2,'Audit Log'!$F$2:$F$2001,$B$3,'Audit Log'!$S$2:$S$2001,$B$4,'Audit Log'!$T$2:$T$2001,"No",'Audit Log'!$P$2:$P$2001,$G2) | I2: =$H2+ROW()/100000 | K2: =IFERROR(INDEX($G$2:$G$14,MATCH(LARGE($I$2:$I$14,1),$I$2:$I$14,0)),"") | L2: =IFERROR(INT(LARGE($I$2:$I$14,1)),0) | N2: Adrales, Allen Rick Aguilar | O2: =COUNTIFS('Audit Log'!$B$2:$B$2001,">="&$B$2,'Audit Log'!$F$2:$F$2001,$N2,'Audit Log'!$S$2:$S$2001,$B$4,'Audit Log'!$T$2:$T$2001,"No") | P2: =COUNTIFS('Audit Log'!$B$2:$B$2001,">="&$B$2,'Audit Log'!$F$2:$F$2001,$N2,'Audit Log'!$S$2:$S$2001,$B$4,'Audit Log'!$T$2:$T$2001,"No",'Audit Log'!$O$2:$O$2001,"Valid") | Q2: =$O2+ROW()/100000 | R2: =IFERROR($P2/$O2,0) | T2: =IFERROR(INDEX($N$2:$N$40,MATCH(LARGE($Q$2:$Q$40,1),$Q$2:$Q$40,0)),"") | U2: =IFERROR(INT(LARGE($Q$2:$Q$40,1)),0) | V2: =IFERROR(INDEX($R$2:$R$40,MATCH(LARGE($Q$2:$Q$40,1),$Q$2:$Q$40,0)),0) | X2: Abad, Roberto Jr Marquez | Y2: =COUNTIFS('Audit Log'!$B$2:$B$2001,">="&$B$2,'Audit Log'!$F$2:$F$2001,$B$3,'Audit Log'!$S$2:$S$2001,$B$4,'Audit Log'!$T$2:$T$2001,"No",'Audit Log'!$C$2:$C$2001,$X2,'Audit Log'!$O$2:$O$2001,"Invalid") | Z2: =$Y2+ROW()/100000 | AB2: =IFERROR(INDEX($X$2:$X$465,MATCH(LARGE($Z$2:$Z$465,1),$Z$2:$Z$465,0)),"") | AC2: =IFERROR(INT(LARGE($Z$2:$Z$465,1)),0)
A3: tlCrit | B3: =IF('Dashboard'!$E$2="All Team Leaders","*",'Dashboard'!$E$2) | D3: =TODAY()-12 | E3: =COUNTIFS('Audit Log'!$B$2:$B$2001,$D3,'Audit Log'!$F$2:$F$2001,$B$3,'Audit Log'!$S$2:$S$2001,$B$4,'Audit Log'!$T$2:$T$2001,"No",'Audit Log'!$O$2:$O$2001,$B$5) | G3: No Support Provided (Security Stop/Hold / Global Trade Fail) | H3: =COUNTIFS('Audit Log'!$B$2:$B$2001,">="&$B$2,'Audit Log'!$F$2:$F$2001,$B$3,'Audit Log'!$S$2:$S$2001,$B$4,'Audit Log'!$T$2:$T$2001,"No",'Audit Log'!$P$2:$P$2001,$G3) | I3: =$H3+ROW()/100000 | K3: =IFERROR(INDEX($G$2:$G$14,MATCH(LARGE($I$2:$I$14,2),$I$2:$I$14,0)),"") | L3: =IFERROR(INT(LARGE($I$2:$I$14,2)),0) | N3: Agustin, Alexander Veloso | O3: =COUNTIFS('Audit Log'!$B$2:$B$2001,">="&$B$2,'Audit Log'!$F$2:$F$2001,$N3,'Audit Log'!$S$2:$S$2001,$B$4,'Audit Log'!$T$2:$T$2001,"No") | P3: =COUNTIFS('Audit Log'!$B$2:$B$2001,">="&$B$2,'Audit Log'!$F$2:$F$2001,$N3,'Audit Log'!$S$2:$S$2001,$B$4,'Audit Log'!$T$2:$T$2001,"No",'Audit Log'!$O$2:$O$2001,"Valid") | Q3: =$O3+ROW()/100000 | R3: =IFERROR($P3/$O3,0) | T3: =IFERROR(INDEX($N$2:$N$40,MATCH(LARGE($Q$2:$Q$40,2),$Q$2:$Q$40,0)),"") | U3: =IFERROR(INT(LARGE($Q$2:$Q$40,2)),0) | V3: =IFERROR(INDEX($R$2:$R$40,MATCH(LARGE($Q$2:$Q$40,2),$Q$2:$Q$40,0)),0) | X3: Abadilla, Paul Justin Aleguiojo | Y3: =COUNTIFS('Audit Log'!$B$2:$B$2001,">="&$B$2,'Audit Log'!$F$2:$F$2001,$B$3,'Audit Log'!$S$2:$S$2001,$B$4,'Audit Log'!$T$2:$T$2001,"No",'Audit Log'!$C$2:$C$2001,$X3,'Audit Log'!$O$2:$O$2001,"Invalid") | Z3: =$Y3+ROW()/100000 | AB3: =IFERROR(INDEX($X$2:$X$465,MATCH(LARGE($Z$2:$Z$465,2),$Z$2:$Z$465,0)),"") | AC3: =IFERROR(INT(LARGE($Z$2:$Z$465,2)),0)
A4: auditorCrit | B4: =IF('Dashboard'!$G$2="All Auditors","*",'Dashboard'!$G$2) | D4: =TODAY()-11 | E4: =COUNTIFS('Audit Log'!$B$2:$B$2001,$D4,'Audit Log'!$F$2:$F$2001,$B$3,'Audit Log'!$S$2:$S$2001,$B$4,'Audit Log'!$T$2:$T$2001,"No",'Audit Log'!$O$2:$O$2001,$B$5) | G4: Cancel Per Customer / No Contact (CPC/NC) | H4: =COUNTIFS('Audit Log'!$B$2:$B$2001,">="&$B$2,'Audit Log'!$F$2:$F$2001,$B$3,'Audit Log'!$S$2:$S$2001,$B$4,'Audit Log'!$T$2:$T$2001,"No",'Audit Log'!$P$2:$P$2001,$G4) | I4: =$H4+ROW()/100000 | K4: =IFERROR(INDEX($G$2:$G$14,MATCH(LARGE($I$2:$I$14,3),$I$2:$I$14,0)),"") | L4: =IFERROR(INT(LARGE($I$2:$I$14,3)),0) | N4: Aluning, Alain-Angelo Cangco | O4: =COUNTIFS('Audit Log'!$B$2:$B$2001,">="&$B$2,'Audit Log'!$F$2:$F$2001,$N4,'Audit Log'!$S$2:$S$2001,$B$4,'Audit Log'!$T$2:$T$2001,"No") | P4: =COUNTIFS('Audit Log'!$B$2:$B$2001,">="&$B$2,'Audit Log'!$F$2:$F$2001,$N4,'Audit Log'!$S$2:$S$2001,$B$4,'Audit Log'!$T$2:$T$2001,"No",'Audit Log'!$O$2:$O$2001,"Valid") | Q4: =$O4+ROW()/100000 | R4: =IFERROR($P4/$O4,0) | T4: =IFERROR(INDEX($N$2:$N$40,MATCH(LARGE($Q$2:$Q$40,3),$Q$2:$Q$40,0)),"") | U4: =IFERROR(INT(LARGE($Q$2:$Q$40,3)),0) | V4: =IFERROR(INDEX($R$2:$R$40,MATCH(LARGE($Q$2:$Q$40,3),$Q$2:$Q$40,0)),0) | X4: Abella, Asianicole Cuambot | Y4: =COUNTIFS('Audit Log'!$B$2:$B$2001,">="&$B$2,'Audit Log'!$F$2:$F$2001,$B$3,'Audit Log'!$S$2:$S$2001,$B$4,'Audit Log'!$T$2:$T$2001,"No",'Audit Log'!$C$2:$C$2001,$X4,'Audit Log'!$O$2:$O$2001,"Invalid") | Z4: =$Y4+ROW()/100000 | AB4: =IFERROR(INDEX($X$2:$X$465,MATCH(LARGE($Z$2:$Z$465,3),$Z$2:$Z$465,0)),"") | AC4: =IFERROR(INT(LARGE($Z$2:$Z$465,3)),0)
A5: valCrit | B5: =IF('Dashboard'!$I$2="All Statuses","*",'Dashboard'!$I$2) | D5: =TODAY()-10 | E5: =COUNTIFS('Audit Log'!$B$2:$B$2001,$D5,'Audit Log'!$F$2:$F$2001,$B$3,'Audit Log'!$S$2:$S$2001,$B$4,'Audit Log'!$T$2:$T$2001,"No",'Audit Log'!$O$2:$O$2001,$B$5) | G5: Case Voided (Test Case / Duplicate / Created by Mistake) | H5: =COUNTIFS('Audit Log'!$B$2:$B$2001,">="&$B$2,'Audit Log'!$F$2:$F$2001,$B$3,'Audit Log'!$S$2:$S$2001,$B$4,'Audit Log'!$T$2:$T$2001,"No",'Audit Log'!$P$2:$P$2001,$G5) | I5: =$H5+ROW()/100000 | K5: =IFERROR(INDEX($G$2:$G$14,MATCH(LARGE($I$2:$I$14,4),$I$2:$I$14,0)),"") | L5: =IFERROR(INT(LARGE($I$2:$I$14,4)),0) | N5: Andrecoso, April Melody Sunga | O5: =COUNTIFS('Audit Log'!$B$2:$B$2001,">="&$B$2,'Audit Log'!$F$2:$F$2001,$N5,'Audit Log'!$S$2:$S$2001,$B$4,'Audit Log'!$T$2:$T$2001,"No") | P5: =COUNTIFS('Audit Log'!$B$2:$B$2001,">="&$B$2,'Audit Log'!$F$2:$F$2001,$N5,'Audit Log'!$S$2:$S$2001,$B$4,'Audit Log'!$T$2:$T$2001,"No",'Audit Log'!$O$2:$O$2001,"Valid") | Q5: =$O5+ROW()/100000 | R5: =IFERROR($P5/$O5,0) | T5: =IFERROR(INDEX($N$2:$N$40,MATCH(LARGE($Q$2:$Q$40,4),$Q$2:$Q$40,0)),"") | U5: =IFERROR(INT(LARGE($Q$2:$Q$40,4)),0) | V5: =IFERROR(INDEX($R$2:$R$40,MATCH(LARGE($Q$2:$Q$40,4),$Q$2:$Q$40,0)),0) | X5: Abella, Ma. Divina Centino | Y5: =COUNTIFS('Audit Log'!$B$2:$B$2001,">="&$B$2,'Audit Log'!$F$2:$F$2001,$B$3,'Audit Log'!$S$2:$S$2001,$B$4,'Audit Log'!$T$2:$T$2001,"No",'Audit Log'!$C$2:$C$2001,$X5,'Audit Log'!$O$2:$O$2001,"Invalid") | Z5: =$Y5+ROW()/100000 | AB5: =IFERROR(INDEX($X$2:$X$465,MATCH(LARGE($Z$2:$Z$465,4),$Z$2:$Z$465,0)),"") | AC5: =IFERROR(INT(LARGE($Z$2:$Z$465,4)),0)
